DEBUG: num_processes=8
DEBUG: Memory config loaded: ram=2048, swp0=16777216
DEBUG: Loaded process 0: time=1, path=input/proc/p0s
DEBUG: Loaded process 1: time=3, path=input/proc/m0s
DEBUG: Loaded process 2: time=5, path=input/proc/s1
DEBUG: Loaded process 3: time=6, path=input/proc/p1s
DEBUG: Loaded process 4: time=9, path=input/proc/s3
DEBUG: Loaded process 5: time=10, path=input/proc/s2
DEBUG: Loaded process 6: time=11, path=input/proc/m1s
DEBUG: Loaded process 7: time=12, path=input/proc/s0
Time slot   0
ld_routine
Time slot   1
	Loaded a process at input/proc/p0s, PID: 1 PRIO: 130
	CPU 3: Dispatched process  1
Time slot   2
liballoc:193
	CPU 3: Put process  1 to run queue
Time slot   3
	CPU 3: Dispatched process  1
liballoc:193
	Loaded a process at input/proc/m0s, PID: 2 PRIO: 120
	CPU 2: Dispatched process  2
liballoc:193
Time slot   4
libfree:217
Time slot   5
liballoc:193
	CPU 3: Put process  1 to run queue
	CPU 3: Dispatched process  1
liballoc:193
	Loaded a process at input/proc/s1, PID: 3 PRIO: 0
Time slot   6
	CPU 1: Dispatched process  3
	CPU 2: Put process  2 to run queue
	CPU 2: Dispatched process  2
libfree:217
	Loaded a process at input/proc/p1s, PID: 4 PRIO: 15
Time slot   7
liballoc:193
	CPU 0: Dispatched process  4
	CPU 3: Put process  1 to run queue
	CPU 3: Dispatched process  1
libread:410
Time slot   8
	CPU 2: Put process  2 to run queue
	CPU 2: Dispatched process  2
	CPU 1: Put process  3 to run queue
	CPU 1: Dispatched process  3
Time slot   9
	CPU 0: Put process  4 to run queue
	CPU 3: Put process  1 to run queue
	CPU 0: Dispatched process  4
	Loaded a process at input/proc/s3, PID: 5 PRIO: 39
	CPU 3: Dispatched process  1
libread:410
Time slot  10
	CPU 1: Put process  3 to run queue
	CPU 1: Dispatched process  3
	CPU 2: Processed  2 has finished
	CPU 2: Dispatched process  5
	Loaded a process at input/proc/s2, PID: 6 PRIO: 120
Time slot  11
	CPU 3: Put process  1 to run queue
	CPU 3: Dispatched process  6
	CPU 0: Put process  4 to run queue
	CPU 0: Dispatched process  4
	Loaded a process at input/proc/m1s, PID: 7 PRIO: 15
Time slot  12
	CPU 2: Put process  5 to run queue
	CPU 1: Put process  3 to run queue
	CPU 2: Dispatched process  7
	CPU 1: Dispatched process  3
liballoc:193
	Loaded a process at input/proc/s0, PID: 8 PRIO: 38
Time slot  13
	CPU 3: Put process  6 to run queue
	CPU 3: Dispatched process  8
	CPU 1: Processed  3 has finished
	CPU 0: Put process  4 to run queue
liballoc:193
	CPU 1: Dispatched process  5
	CPU 0: Dispatched process  4
	CPU 2: Put process  7 to run queue
	CPU 2: Dispatched process  7
libfree:217
Time slot  14
	CPU 3: Put process  8 to run queue
	CPU 3: Dispatched process  8
Time slot  15
liballoc:193
	CPU 1: Put process  5 to run queue
	CPU 1: Dispatched process  5
	CPU 0: Put process  4 to run queue
	CPU 0: Dispatched process  4
	CPU 2: Put process  7 to run queue
Time slot  16
	CPU 2: Dispatched process  7
libfree:217
	CPU 3: Put process  8 to run queue
	CPU 3: Dispatched process  8
Time slot  17
	CPU 0: Processed  4 has finished
	CPU 0: Dispatched process  6
libfree:217
	CPU 1: Put process  5 to run queue
	CPU 1: Dispatched process  5
	CPU 2: Processed  7 has finished
Time slot  18
	CPU 2: Dispatched process  1
libread:410
	CPU 3: Put process  8 to run queue
	CPU 3: Dispatched process  8
Time slot  19
	CPU 1: Put process  5 to run queue
	CPU 1: Dispatched process  5
	CPU 0: Put process  6 to run queue
	CPU 0: Dispatched process  6
Time slot  20
	CPU 2: Put process  1 to run queue
	CPU 2: Dispatched process  1
libfree:217
	CPU 3: Put process  8 to run queue
	CPU 3: Dispatched process  8
Time slot  21
	CPU 1: Put process  5 to run queue
	CPU 0: Put process  6 to run queue
	CPU 1: Dispatched process  5
	CPU 0: Dispatched process  6
Time slot  22
	CPU 2: Processed  1 has finished
	CPU 2 stopped
	CPU 1: Processed  5 has finished
	CPU 1 stopped
Time slot  23
	CPU 0: Put process  6 to run queue
	CPU 0: Dispatched process  6
	CPU 3: Put process  8 to run queue
	CPU 3: Dispatched process  8
Time slot  24
Time slot  25
	CPU 0: Put process  6 to run queue
	CPU 0: Dispatched process  6
	CPU 3: Put process  8 to run queue
	CPU 3: Dispatched process  8
Time slot  26
Time slot  27
	CPU 0: Processed  6 has finished
	CPU 0 stopped
	CPU 3: Put process  8 to run queue
	CPU 3: Dispatched process  8
Time slot  28
	CPU 3: Processed  8 has finished
	CPU 3 stopped
