Time slot   0
ld_routine
Time slot   1
	Loaded a process at input/proc/p1s, PID: 1 PRIO: 15
	CPU 1: Dispatched process  1
Time slot   2
Time slot   3
	CPU 1: Put process  1 to run queue
	CPU 1: Dispatched process  1
Time slot   4
	Loaded a process at input/proc/m0s, PID: 2 PRIO: 120
Time slot   5
	CPU 2: Dispatched process  2
	CPU 1: Put process  1 to run queue
	CPU 1: Dispatched process  1
liballoc:193
print_pgtbl:
 PDG=000001C6F4235A50 P4g=000001C6F4236A60 PUD=000001C6F5FEE010 PMD=000001C6F5FEF020
Time slot   6
liballoc:193
print_pgtbl:
 PDG=000001C6F4235A50 P4g=000001C6F4236A60 PUD=000001C6F5FEE010 PMD=000001C6F5FEF020
Time slot   7
	CPU 1: Put process  1 to run queue
	CPU 1: Dispatched process  1
	CPU 2: Put process  2 to run queue
	CPU 2: Dispatched process  2
libfree:217
print_pgtbl:
 PDG=000001C6F4235A50 P4g=000001C6F4236A60 PUD=000001C6F5FEE010 PMD=000001C6F5FEF020
	Loaded a process at input/proc/p0s, PID: 3 PRIO: 130
	CPU 3: Dispatched process  3
Time slot   8
liballoc:193
print_pgtbl:
 PDG=000001C6F4235A50 P4g=000001C6F4236A60 PUD=000001C6F5FEE010 PMD=000001C6F5FEF020
Time slot   9
	CPU 2: Put process  2 to run queue
	CPU 1: Put process  1 to run queue
	Loaded a process at input/proc/s0, PID: 4 PRIO: 38
	CPU 2: Dispatched process  2
liballoc:193
print_pgtbl:
 PDG=000001C6F481F080 P4g=000001C6F48240D0 PUD=000001C6F48220B0 PMD=000001C6F48230C0
libwrite:489
print_pgtbl:
 PDG=000001C6F4235A50 P4g=000001C6F4236A60 PUD=000001C6F5FEE010 PMD=000001C6F5FEF020
	CPU 1: Dispatched process  1
Time slot  10
	CPU 0: Dispatched process  4
	CPU 3: Put process  3 to run queue
	CPU 3: Dispatched process  3
liballoc:193
print_pgtbl:
 PDG=000001C6F481F080 P4g=000001C6F48240D0 PUD=000001C6F48220B0 PMD=000001C6F48230C0
libwrite:489
print_pgtbl:
 PDG=000001C6F4235A50 P4g=000001C6F4236A60 PUD=000001C6F5FEE010 PMD=000001C6F5FEF020
libfree:217
print_pgtbl:
 PDG=000001C6F481F080 P4g=000001C6F48240D0 PUD=000001C6F48220B0 PMD=000001C6F48230C0
Time slot  11
	CPU 2: Processed  2 has finished
	CPU 1: Processed  1 has finished
	Loaded a process at input/proc/s3, PID: 5 PRIO: 39
	CPU 3: Put process  3 to run queue
	CPU 3: Dispatched process  5
Time slot  12
	CPU 2: Dispatched process  3
	CPU 0: Put process  4 to run queue
liballoc:193
	CPU 0: Dispatched process  4
print_pgtbl:
 PDG=000001C6F481F080 P4g=000001C6F48240D0 PUD=000001C6F48220B0 PMD=000001C6F48230C0
Time slot  13
libwrite:489
print_pgtbl:
 PDG=000001C6F481F080 P4g=000001C6F48240D0 PUD=000001C6F48220B0 PMD=000001C6F48230C0
	Loaded a process at input/proc/m1s, PID: 6 PRIO: 15
	CPU 3: Put process  5 to run queue
Time slot  14
	CPU 3: Dispatched process  6
	CPU 2: Put process  3 to run queue
	CPU 2: Dispatched process  3
libread:434
print_pgtbl:
 PDG=000001C6F481F080 P4g=000001C6F48240D0 PUD=000001C6F48220B0 PMD=000001C6F48230C0
	CPU 1: Dispatched process  5
	CPU 0: Put process  4 to run queue
liballoc:193
print_pgtbl:
 PDG=000001C6F48260F0 P4g=000001C6F482A130 PUD=000001C6F482B140 PMD=000001C6F482C150
	CPU 0: Dispatched process  4
liballoc:193
print_pgtbl:
 PDG=000001C6F48260F0 P4g=000001C6F482A130 PUD=000001C6F482B140 PMD=000001C6F482C150
libwrite:489
print_pgtbl:
 PDG=000001C6F481F080 P4g=000001C6F48240D0 PUD=000001C6F48220B0 PMD=000001C6F48230C0
Time slot  15
	Loaded a process at input/proc/s2, PID: 7 PRIO: 120
	CPU 1: Put process  5 to run queue
Time slot  16
	CPU 1: Dispatched process  5
	CPU 3: Put process  6 to run queue
	CPU 3: Dispatched process  6
	CPU 0: Put process  4 to run queue
libfree:217
	CPU 0: Dispatched process  4
	CPU 2: Put process  3 to run queue
print_pgtbl:
 PDG=000001C6F48260F0 P4g=000001C6F482A130 PUD=000001C6F482B140 PMD=000001C6F482C150
	CPU 2: Dispatched process  7
liballoc:193
print_pgtbl:
 PDG=000001C6F48260F0 P4g=000001C6F482A130 PUD=000001C6F482B140 PMD=000001C6F482C150
Time slot  17
	Loaded a process at input/proc/s1, PID: 8 PRIO: 0
Time slot  18
	CPU 2: Put process  7 to run queue
	CPU 2: Dispatched process  8
	CPU 0: Put process  4 to run queue
	CPU 0: Dispatched process  4
	CPU 3: Put process  6 to run queue
	CPU 3: Dispatched process  6
libfree:217
print_pgtbl:
 PDG=000001C6F48260F0 P4g=000001C6F482A130 PUD=000001C6F482B140 PMD=000001C6F482C150
	CPU 1: Put process  5 to run queue
	CPU 1: Dispatched process  5
libfree:217
print_pgtbl:
 PDG=000001C6F48260F0 P4g=000001C6F482A130 PUD=000001C6F482B140 PMD=000001C6F482C150
Time slot  19
Time slot  20
	CPU 3: Processed  6 has finished
	CPU 2: Put process  8 to run queue
	CPU 3: Dispatched process  7
	CPU 2: Dispatched process  8
	CPU 1: Put process  5 to run queue
	CPU 1: Dispatched process  5
	CPU 0: Put process  4 to run queue
	CPU 0: Dispatched process  4
Time slot  21
	CPU 3: Put process  7 to run queue
	CPU 3: Dispatched process  7
Time slot  22
	CPU 2: Put process  8 to run queue
	CPU 2: Dispatched process  8
	CPU 0: Put process  4 to run queue
	CPU 1: Put process  5 to run queue
	CPU 0: Dispatched process  4
	CPU 1: Dispatched process  5
Time slot  23
	CPU 1: Processed  5 has finished
	CPU 1: Dispatched process  3
print_pgtbl:
 PDG=000001C6F481F080 P4g=000001C6F48240D0 PUD=000001C6F48220B0 PMD=000001C6F48230C0
	CPU 3: Put process  7 to run queue
	CPU 3: Dispatched process  7
Time slot  24
	CPU 2: Put process  8 to run queue
	CPU 2: Dispatched process  8
libwrite:489
	CPU 0: Put process  4 to run queue
print_pgtbl:
 PDG=000001C6F481F080 P4g=000001C6F48240D0 PUD=000001C6F48220B0 PMD=000001C6F48230C0
	CPU 0: Dispatched process  4
Time slot  25
	CPU 2: Processed  8 has finished
	CPU 0: Processed  4 has finished
	CPU 1: Put process  3 to run queue
	CPU 2 stopped
	CPU 1: Dispatched process  3
print_pgtbl:
 PDG=000001C6F481F080 P4g=000001C6F48240D0 PUD=000001C6F48220B0 PMD=000001C6F48230C0
	CPU 0 stopped
Time slot  26
	CPU 3: Put process  7 to run queue
	CPU 3: Dispatched process  7
Time slot  27
	CPU 1: Put process  3 to run queue
	CPU 1: Dispatched process  3
libfree:217
print_pgtbl:
 PDG=000001C6F481F080 P4g=000001C6F48240D0 PUD=000001C6F48220B0 PMD=000001C6F48230C0
Time slot  28
	CPU 3: Put process  7 to run queue
	CPU 3: Dispatched process  7
Time slot  29
	CPU 1: Processed  3 has finished
	CPU 1 stopped
Time slot  30
	CPU 3: Processed  7 has finished
	CPU 3 stopped
