DEBUG: num_processes=8
DEBUG: Memory config loaded: ram=268435456, swp0=16777216
DEBUG: Loaded process 0: time=1, path=input/proc/p1s
DEBUG: Loaded process 1: time=5, path=input/proc/m0s
DEBUG: Loaded process 2: time=7, path=input/proc/p0s
DEBUG: Loaded process 3: time=9, path=input/proc/s0
DEBUG: Loaded process 4: time=11, path=input/proc/s3
DEBUG: Loaded process 5: time=14, path=input/proc/m1s
DEBUG: Loaded process 6: time=16, path=input/proc/s2
DEBUG: Loaded process 7: time=16, path=input/proc/s1
Time slot   0
ld_routine
Time slot   1
	Loaded a process at input/proc/p1s, PID: 1 PRIO: 15
	CPU 0: Dispatched process  1
Time slot   2
Time slot   3
	CPU 0: Put process  1 to run queue
	CPU 0: Dispatched process  1
Time slot   4
Time slot   5
	CPU 0: Put process  1 to run queue
	CPU 0: Dispatched process  1
	Loaded a process at input/proc/m0s, PID: 2 PRIO: 120
Time slot   6
	CPU 3: Dispatched process  2
liballoc:193
Time slot   7
liballoc:193
	CPU 0: Put process  1 to run queue
	CPU 0: Dispatched process  1
	Loaded a process at input/proc/p0s, PID: 3 PRIO: 130
Time slot   8
	CPU 3: Put process  2 to run queue
	CPU 3: Dispatched process  2
libfree:217
	CPU 2: Dispatched process  3
Time slot   9
liballoc:193
	CPU 0: Put process  1 to run queue
	CPU 0: Dispatched process  1
	Loaded a process at input/proc/s0, PID: 4 PRIO: 38
liballoc:193
Time slot  10
	CPU 3: Put process  2 to run queue
	CPU 3: Dispatched process  4
	CPU 2: Put process  3 to run queue
	CPU 2: Dispatched process  2
	CPU 1: Dispatched process  3
liballoc:193
libwrite:472
Time slot  11
libfree:217
	CPU 0: Processed  1 has finished
libwrite:472
	Loaded a process at input/proc/s3, PID: 5 PRIO: 39
Time slot  12
	CPU 2: Processed  2 has finished
	CPU 3: Put process  4 to run queue
	CPU 1: Put process  3 to run queue
	CPU 1: Dispatched process  5
	CPU 2: Dispatched process  4
	CPU 3: Dispatched process  3
liballoc:193
Time slot  13
libwrite:472
Time slot  14
	CPU 1: Put process  5 to run queue
	CPU 3: Put process  3 to run queue
	CPU 1: Dispatched process  5
	CPU 3: Dispatched process  3
libread:410
libread:417
	CPU 2: Put process  4 to run queue
	CPU 2: Dispatched process  4
	Loaded a process at input/proc/m1s, PID: 6 PRIO: 15
Time slot  15
	CPU 0: Dispatched process  6
liballoc:193
libwrite:472
Time slot  16
	CPU 2: Put process  4 to run queue
	CPU 2: Dispatched process  4
liballoc:193
	CPU 1: Put process  5 to run queue
	CPU 1: Dispatched process  5
	CPU 3: Put process  3 to run queue
	CPU 3: Dispatched process  3
libread:410
	Loaded a process at input/proc/s2, PID: 7 PRIO: 120
Time slot  17
	CPU 0: Put process  6 to run queue
	CPU 0: Dispatched process  6
libfree:217
libwrite:472
	Loaded a process at input/proc/s1, PID: 8 PRIO: 0
Time slot  18
	CPU 2: Put process  4 to run queue
	CPU 2: Dispatched process  8
	CPU 1: Put process  5 to run queue
	CPU 1: Dispatched process  4
	CPU 3: Put process  3 to run queue
liballoc:193
	CPU 3: Dispatched process  5
Time slot  19
	CPU 0: Put process  6 to run queue
	CPU 0: Dispatched process  6
libfree:217
Time slot  20
	CPU 3: Put process  5 to run queue
	CPU 3: Dispatched process  5
	CPU 1: Put process  4 to run queue
libfree:217
	CPU 2: Put process  8 to run queue
	CPU 1: Dispatched process  4
	CPU 2: Dispatched process  8
Time slot  21
	CPU 0: Processed  6 has finished
	CPU 0: Dispatched process  7
Time slot  22
	CPU 2: Put process  8 to run queue
	CPU 2: Dispatched process  8
	CPU 3: Put process  5 to run queue
	CPU 3: Dispatched process  5
	CPU 1: Put process  4 to run queue
	CPU 1: Dispatched process  4
	CPU 3: Processed  5 has finished
Time slot  23
	CPU 3: Dispatched process  3
libread:410
	CPU 0: Put process  7 to run queue
	CPU 0: Dispatched process  7
	CPU 2: Put process  8 to run queue
	CPU 1: Put process  4 to run queue
Time slot  24
	CPU 2: Dispatched process  8
	CPU 1: Dispatched process  4
	CPU 3: Put process  3 to run queue
	CPU 3: Dispatched process  3
libfree:217
Time slot  25
	CPU 2: Processed  8 has finished
	CPU 1: Processed  4 has finished
	CPU 0: Put process  7 to run queue
	CPU 2 stopped
	CPU 1 stopped
	CPU 0: Dispatched process  7
Time slot  26
Time slot  27
	CPU 3: Processed  3 has finished
	CPU 0: Put process  7 to run queue
	CPU 0: Dispatched process  7
	CPU 3 stopped
Time slot  28
Time slot  29
	CPU 0: Put process  7 to run queue
	CPU 0: Dispatched process  7
Time slot  30
Time slot  31
	CPU 0: Put process  7 to run queue
	CPU 0: Dispatched process  7
Time slot  32
Time slot  33
	CPU 0: Processed  7 has finished
	CPU 0 stopped
