Time slot   0
ld_routine
Time slot   1
	Loaded a process at input/proc/p1s, PID: 1 PRIO: 15
Time slot   2
	CPU 3: Dispatched process  1
Time slot   3
	CPU 3: Put process  1 to run queue
	CPU 3: Dispatched process  1
Time slot   4
Time slot   5
	Loaded a process at input/proc/m0s, PID: 2 PRIO: 120
	CPU 1: Dispatched process  2
liballoc:193
print_pgtbl:
 PDG=0000021BF7F05960 P4g=0000021BF7F06970 PUD=0000021BF9CBE020 PMD=0000021BF9CBF030
	CPU 3: Put process  1 to run queue
	CPU 3: Dispatched process  1
Time slot   6
liballoc:193
print_pgtbl:
 PDG=0000021BF7F05960 P4g=0000021BF7F06970 PUD=0000021BF9CBE020 PMD=0000021BF9CBF030
Time slot   7
	CPU 1: Put process  2 to run queue
	CPU 1: Dispatched process  2
libfree:217
print_pgtbl:
 PDG=0000021BF7F05960 P4g=0000021BF7F06970 PUD=0000021BF9CBE020 PMD=0000021BF9CBF030
	Loaded a process at input/proc/p0s, PID: 3 PRIO: 130
	CPU 3: Put process  1 to run queue
	CPU 3: Dispatched process  1
Time slot   8
	CPU 2: Dispatched process  3
liballoc:193
print_pgtbl:
 PDG=0000021BF7F05960 P4g=0000021BF7F06970 PUD=0000021BF9CBE020 PMD=0000021BF9CBF030
	Loaded a process at input/proc/s0, PID: 4 PRIO: 38
Time slot   9
	CPU 1: Put process  2 to run queue
	CPU 1: Dispatched process  4
liballoc:193
print_pgtbl:
 PDG=0000021BFA216090 P4g=0000021BFA2180B0 PUD=0000021BFA21A0D0 PMD=0000021BFA21C0F0
	CPU 0: Dispatched process  2
libwrite:489
print_pgtbl:
 PDG=0000021BF7F05960 P4g=0000021BF7F06970 PUD=0000021BF9CBE020 PMD=0000021BF9CBF030
	CPU 3: Put process  1 to run queue
	CPU 3: Dispatched process  1
Time slot  10
	CPU 2: Put process  3 to run queue
	CPU 2: Dispatched process  3
liballoc:193
print_pgtbl:
 PDG=0000021BFA216090 P4g=0000021BFA2180B0 PUD=0000021BFA21A0D0 PMD=0000021BFA21C0F0
libwrite:489
print_pgtbl:
 PDG=0000021BF7F05960 P4g=0000021BF7F06970 PUD=0000021BF9CBE020 PMD=0000021BF9CBF030
	Loaded a process at input/proc/s3, PID: 5 PRIO: 39
Time slot  11
libfree:217
print_pgtbl:
 PDG=0000021BFA216090 P4g=0000021BFA2180B0 PUD=0000021BFA21A0D0 PMD=0000021BFA21C0F0
	CPU 1: Put process  4 to run queue
	CPU 1: Dispatched process  4
	CPU 0: Processed  2 has finished
	CPU 0: Dispatched process  5
	CPU 3: Processed  1 has finished
Time slot  12
	CPU 2: Put process  3 to run queue
	CPU 2: Dispatched process  3
liballoc:193
print_pgtbl:
 PDG=0000021BFA216090 P4g=0000021BFA2180B0 PUD=0000021BFA21A0D0 PMD=0000021BFA21C0F0
Time slot  13
	CPU 0: Put process  5 to run queue
	CPU 1: Put process  4 to run queue
libwrite:489
	CPU 1: Dispatched process  4
	CPU 0: Dispatched process  5
print_pgtbl:
 PDG=0000021BFA216090 P4g=0000021BFA2180B0 PUD=0000021BFA21A0D0 PMD=0000021BFA21C0F0
	Loaded a process at input/proc/m1s, PID: 6 PRIO: 15
	CPU 2: Put process  3 to run queue
Time slot  14
	CPU 2: Dispatched process  6
liballoc:193
print_pgtbl:
 PDG=0000021BFA21F120 P4g=0000021BFA220130 PUD=0000021BFA221140 PMD=0000021BFA222150
	CPU 3: Dispatched process  3
Time slot  15
liballoc:193
libread:434
print_pgtbl:
 PDG=0000021BFA216090 P4g=0000021BFA2180B0 PUD=0000021BFA21A0D0 PMD=0000021BFA21C0F0
print_pgtbl:
 PDG=0000021BFA21F120 P4g=0000021BFA220130 PUD=0000021BFA221140 PMD=0000021BFA222150
	CPU 1: Put process  4 to run queue
	CPU 1: Dispatched process  4
	CPU 0: Put process  5 to run queue
	CPU 0: Dispatched process  5
	Loaded a process at input/proc/s2, PID: 7 PRIO: 120
libwrite:489
print_pgtbl:
 PDG=0000021BFA216090 P4g=0000021BFA2180B0 PUD=0000021BFA21A0D0 PMD=0000021BFA21C0F0
	CPU 2: Put process  6 to run queue
	CPU 2: Dispatched process  6
Time slot  16
libfree:217
print_pgtbl:
 PDG=0000021BFA21F120 P4g=0000021BFA220130 PUD=0000021BFA221140 PMD=0000021BFA222150
	CPU 3: Put process  3 to run queue
	CPU 3: Dispatched process  7
Time slot  17
liballoc:193
print_pgtbl:
 PDG=0000021BFA21F120 P4g=0000021BFA220130 PUD=0000021BFA221140 PMD=0000021BFA222150
	CPU 1: Put process  4 to run queue
	CPU 1: Dispatched process  4
	CPU 0: Put process  5 to run queue
	CPU 0: Dispatched process  5
	Loaded a process at input/proc/s1, PID: 8 PRIO: 0
	CPU 2: Put process  6 to run queue
	CPU 2: Dispatched process  8
Time slot  18
	CPU 3: Put process  7 to run queue
	CPU 3: Dispatched process  6
libfree:217
print_pgtbl:
 PDG=0000021BFA21F120 P4g=0000021BFA220130 PUD=0000021BFA221140 PMD=0000021BFA222150
Time slot  19
	CPU 1: Put process  4 to run queue
	CPU 1: Dispatched process  4
	CPU 0: Put process  5 to run queue
	CPU 0: Dispatched process  5
libfree:217
print_pgtbl:
 PDG=0000021BFA21F120 P4g=0000021BFA220130 PUD=0000021BFA221140 PMD=0000021BFA222150
Time slot  20
	CPU 2: Put process  8 to run queue
	CPU 2: Dispatched process  8
	CPU 3: Processed  6 has finished
Time slot  21
	CPU 3: Dispatched process  7
	CPU 1: Put process  4 to run queue
	CPU 0: Put process  5 to run queue
	CPU 1: Dispatched process  4
	CPU 0: Dispatched process  5
Time slot  22
	CPU 2: Put process  8 to run queue
	CPU 2: Dispatched process  8
	CPU 0: Processed  5 has finished
	CPU 0: Dispatched process  3
print_pgtbl:
 PDG=0000021BFA216090 P4g=0000021BFA2180B0 PUD=0000021BFA21A0D0 PMD=0000021BFA21C0F0
	CPU 3: Put process  7 to run queue
	CPU 3: Dispatched process  7
Time slot  23
	CPU 1: Put process  4 to run queue
	CPU 1: Dispatched process  4
libwrite:489
print_pgtbl:
 PDG=0000021BFA216090 P4g=0000021BFA2180B0 PUD=0000021BFA21A0D0 PMD=0000021BFA21C0F0
Time slot  24
	CPU 2: Put process  8 to run queue
	CPU 2: Dispatched process  8
	CPU 1: Processed  4 has finished
	CPU 1 stopped
	CPU 0: Put process  3 to run queue
	CPU 0: Dispatched process  3
print_pgtbl:
 PDG=0000021BFA216090 P4g=0000021BFA2180B0 PUD=0000021BFA21A0D0 PMD=0000021BFA21C0F0
	CPU 3: Put process  7 to run queue
Time slot  25
	CPU 3: Dispatched process  7
	CPU 2: Processed  8 has finished
	CPU 2 stopped
Time slot  26
	CPU 0: Put process  3 to run queue
	CPU 0: Dispatched process  3
libfree:217
print_pgtbl:
 PDG=0000021BFA216090 P4g=0000021BFA2180B0 PUD=0000021BFA21A0D0 PMD=0000021BFA21C0F0
Time slot  27
	CPU 3: Put process  7 to run queue
	CPU 3: Dispatched process  7
Time slot  28
	CPU 0: Processed  3 has finished
	CPU 0 stopped
Time slot  29
	CPU 3: Put process  7 to run queue
	CPU 3: Dispatched process  7
Time slot  30
Time slot  31
	CPU 3: Processed  7 has finished
	CPU 3 stopped
