Time slot   0
ld_routine
Time slot   1
	Loaded a process at input/proc/p0s, PID: 1 PRIO: 130
	CPU 3: Dispatched process  1
Time slot   2
Time slot   3
	Loaded a process at input/proc/m0s, PID: 2 PRIO: 120
liballoc:193
print_pgtbl:
 PDG=0000000000000000 P4g=0000000000000000 PUD=0000000000000000 PMD=0000000000000000
	CPU 2: Dispatched process  2
liballoc:193
print_pgtbl:
 PDG=0000000000000000 P4g=0000000000000000 PUD=0000000000000000 PMD=0000000000000000
	CPU 3: Put process  1 to run queue
liballoc:193
	CPU 3: Dispatched process  1
print_pgtbl:
Time slot   4
 PDG=0000000000000000 P4g=0000000000000000 PUD=0000000000000000 PMD=0000000000000000
liballoc:193
print_pgtbl:
 PDG=0000000000000000 P4g=0000000000000000 PUD=0000000000000000 PMD=0000000000000000
Time slot   5
libfree:217
print_pgtbl:
 PDG=0000000000000000 P4g=0000000000000000 PUD=0000000000000000 PMD=0000000000000000
	Loaded a process at input/proc/s1, PID: 3 PRIO: 0
	CPU 2: Put process  2 to run queue
	CPU 2: Dispatched process  3
	CPU 1: Dispatched process  2
libfree:217
print_pgtbl:
 PDG=0000000000000000 P4g=0000000000000000 PUD=0000000000000000 PMD=0000000000000000
Time slot   6
	CPU 3: Put process  1 to run queue
	CPU 3: Dispatched process  1
liballoc:193
print_pgtbl:
 PDG=0000000000000000 P4g=0000000000000000 PUD=0000000000000000 PMD=0000000000000000
liballoc:193
print_pgtbl:
 PDG=0000000000000000 P4g=0000000000000000 PUD=0000000000000000 PMD=0000000000000000
	Loaded a process at input/proc/p1s, PID: 4 PRIO: 15
Time slot   7
	CPU 2: Put process  3 to run queue
	CPU 2: Dispatched process  3
	CPU 1: Put process  2 to run queue
	CPU 1: Dispatched process  4
	CPU 0: Dispatched process  2
	CPU 3: Put process  1 to run queue
Time slot   8
	CPU 3: Dispatched process  1
print_pgtbl:
 PDG=0000000000000000 P4g=0000000000000000 PUD=0000000000000000 PMD=0000000000000000
Time slot   9
	Loaded a process at input/proc/s3, PID: 5 PRIO: 39
	CPU 0: Processed  2 has finished
	CPU 2: Put process  3 to run queue
	CPU 0: Dispatched process  5
	CPU 2: Dispatched process  3
	CPU 1: Put process  4 to run queue
	CPU 1: Dispatched process  4
	CPU 3: Put process  1 to run queue
Time slot  10
	CPU 3: Dispatched process  1
print_pgtbl:
 PDG=0000000000000000 P4g=0000000000000000 PUD=0000000000000000 PMD=0000000000000000
	Loaded a process at input/proc/s2, PID: 6 PRIO: 120
Time slot  11
	CPU 2: Put process  3 to run queue
	CPU 2: Dispatched process  3
	CPU 1: Put process  4 to run queue
	CPU 0: Put process  5 to run queue
	CPU 1: Dispatched process  4
	CPU 0: Dispatched process  5
	Loaded a process at input/proc/m1s, PID: 7 PRIO: 15
Time slot  12
	CPU 2: Processed  3 has finished
	CPU 3: Put process  1 to run queue
	CPU 2: Dispatched process  7
	CPU 3: Dispatched process  6
liballoc:193
print_pgtbl:
 PDG=0000000000000000 P4g=0000000000000000 PUD=0000000000000000 PMD=0000000000000000
	Loaded a process at input/proc/s0, PID: 8 PRIO: 38
Time slot  13
liballoc:193
print_pgtbl:
 PDG=0000000000000000 P4g=0000000000000000 PUD=0000000000000000 PMD=0000000000000000
	CPU 1: Put process  4 to run queue
	CPU 1: Dispatched process  4
	CPU 0: Put process  5 to run queue
	CPU 0: Dispatched process  8
	CPU 3: Put process  6 to run queue
	CPU 3: Dispatched process  5
Time slot  14
	CPU 2: Put process  7 to run queue
	CPU 2: Dispatched process  7
libfree:217
print_pgtbl:
 PDG=0000000000000000 P4g=0000000000000000 PUD=0000000000000000 PMD=0000000000000000
Time slot  15
	CPU 1: Put process  4 to run queue
liballoc:193
	CPU 1: Dispatched process  4
print_pgtbl:
 PDG=0000000000000000 P4g=0000000000000000 PUD=0000000000000000 PMD=0000000000000000
	CPU 0: Put process  8 to run queue
	CPU 0: Dispatched process  8
	CPU 3: Put process  5 to run queue
Time slot  16
	CPU 3: Dispatched process  5
	CPU 2: Put process  7 to run queue
	CPU 2: Dispatched process  7
libfree:217
print_pgtbl:
 PDG=0000000000000000 P4g=0000000000000000 PUD=0000000000000000 PMD=0000000000000000
libfree:217
print_pgtbl:
 PDG=0000000000000000 P4g=0000000000000000 PUD=0000000000000000 PMD=0000000000000000
	CPU 1: Processed  4 has finished
Time slot  17
	CPU 1: Dispatched process  6
	CPU 0: Put process  8 to run queue
	CPU 0: Dispatched process  8
	CPU 3: Put process  5 to run queue
	CPU 3: Dispatched process  5
Time slot  18
	CPU 2: Processed  7 has finished
	CPU 2: Dispatched process  1
print_pgtbl:
 PDG=0000000000000000 P4g=0000000000000000 PUD=0000000000000000 PMD=0000000000000000
	CPU 1: Put process  6 to run queue
Time slot  19
	CPU 1: Dispatched process  6
	CPU 0: Put process  8 to run queue
	CPU 0: Dispatched process  8
	CPU 3: Put process  5 to run queue
	CPU 3: Dispatched process  5
Time slot  20
	CPU 2: Put process  1 to run queue
	CPU 2: Dispatched process  1
libfree:217
print_pgtbl:
 PDG=0000000000000000 P4g=0000000000000000 PUD=0000000000000000 PMD=0000000000000000
	CPU 3: Processed  5 has finished
Time slot  21
	CPU 3 stopped
	CPU 1: Put process  6 to run queue
	CPU 1: Dispatched process  6
	CPU 0: Put process  8 to run queue
	CPU 0: Dispatched process  8
	CPU 2: Processed  1 has finished
Time slot  22
	CPU 2 stopped
Time slot  23
	CPU 1: Put process  6 to run queue
	CPU 0: Put process  8 to run queue
	CPU 1: Dispatched process  6
	CPU 0: Dispatched process  8
Time slot  24
Time slot  25
	CPU 1: Put process  6 to run queue
	CPU 0: Put process  8 to run queue
	CPU 1: Dispatched process  6
	CPU 0: Dispatched process  8
Time slot  26
Time slot  27
	CPU 1: Processed  6 has finished
	CPU 0: Put process  8 to run queue
	CPU 1 stopped
	CPU 0: Dispatched process  8
Time slot  28
	CPU 0: Processed  8 has finished
	CPU 0 stopped
