Time slot   0
ld_routine
Time slot   1
	Loaded a process at input/proc/p0s, PID: 1 PRIO: 130
	CPU 1: Dispatched process  1
Time slot   2
liballoc:193
print_pgtbl:
 PDG=00000266c02cc850 P4g=00000266c02cd860 PUD=00000266c02ce870 PMD=00000266c02cf880
	Loaded a process at input/proc/m0s, PID: 2 PRIO: 120
	CPU 3: Dispatched process  2
Time slot   3
liballoc:193
print_pgtbl:
 PDG=0000000000000000 P4g=0000000000000000 PUD=0000000000000000 PMD=0000000000000000
	CPU 1: Put process  1 to run queue
	CPU 1: Dispatched process  1
liballoc:193
print_pgtbl:
 PDG=00000266c02cc850 P4g=00000266c02cd860 PUD=00000266c02ce870 PMD=00000266c02cf880
Time slot   4
liballoc:193
	Loaded a process at input/proc/s3, PID: 3 PRIO: 39
print_pgtbl:
 PDG=0000000000000000 P4g=0000000000000000 PUD=0000000000000000 PMD=0000000000000000
libfree:217
print_pgtbl:
 PDG=00000266c02cc850 P4g=00000266c02cd860 PUD=00000266c02ce870 PMD=00000266c02cf880
Time slot   5
	CPU 2: Dispatched process  3
	CPU 1: Put process  1 to run queue
	CPU 3: Put process  2 to run queue
	CPU 1: Dispatched process  1
	CPU 3: Dispatched process  2
liballoc:193
print_pgtbl:
 PDG=00000266c02cc850 P4g=00000266c02cd860 PUD=00000266c02ce870 PMD=00000266c02cf880
libfree:217
print_pgtbl:
 PDG=0000000000000000 P4g=0000000000000000 PUD=0000000000000000 PMD=0000000000000000
	Loaded a process at input/proc/s0, PID: 4 PRIO: 38
liballoc:193
Time slot   6
print_pgtbl:
 PDG=0000000000000000 P4g=0000000000000000 PUD=0000000000000000 PMD=0000000000000000
libwrite:471
print_pgtbl:
 PDG=00000266c02cc850 P4g=00000266c02cd860 PUD=00000266c02ce870 PMD=00000266c02cf880
	CPU 0: Dispatched process  4
	CPU 3: Put process  2 to run queue
Time slot   7
	CPU 3: Dispatched process  2
	CPU 1: Put process  1 to run queue
	CPU 2: Put process  3 to run queue
	CPU 1: Dispatched process  1
	CPU 2: Dispatched process  3
libread:416
print_pgtbl:
 PDG=00000266c02cc850 P4g=00000266c02cd860 PUD=00000266c02ce870 PMD=00000266c02cf880
Time slot   8
libwrite:471
print_pgtbl:
 PDG=00000266c02cc850 P4g=00000266c02cd860 PUD=00000266c02ce870 PMD=00000266c02cf880
	CPU 0: Put process  4 to run queue
	CPU 0: Dispatched process  4
	CPU 2: Put process  3 to run queue
	CPU 3: Processed  2 has finished
	CPU 2: Dispatched process  3
Time slot   9
	CPU 1: Put process  1 to run queue
	Loaded a process at input/proc/m1s, PID: 5 PRIO: 15
	CPU 1: Dispatched process  1
print_pgtbl:
 PDG=00000266c02cc850 P4g=00000266c02cd860 PUD=00000266c02ce870 PMD=00000266c02cf880
	CPU 3: Dispatched process  5
Time slot  10
liballoc:193
print_pgtbl:
 PDG=0000000000000000 P4g=0000000000000000 PUD=0000000000000000 PMD=0000000000000000
libwrite:471
print_pgtbl:
 PDG=00000266c02cc850 P4g=00000266c02cd860 PUD=00000266c02ce870 PMD=00000266c02cf880
	CPU 0: Put process  4 to run queue
	CPU 0: Dispatched process  4
Time slot  11
	Loaded a process at input/proc/p1s, PID: 6 PRIO: 15
	CPU 1: Put process  1 to run queue
liballoc:193
	CPU 2: Put process  3 to run queue
	CPU 1: Dispatched process  6
print_pgtbl:
 PDG=0000000000000000 P4g=0000000000000000 PUD=0000000000000000 PMD=0000000000000000
	CPU 2: Dispatched process  3
	CPU 3: Put process  5 to run queue
	CPU 3: Dispatched process  5
Time slot  12
libfree:217
print_pgtbl:
 PDG=0000000000000000 P4g=0000000000000000 PUD=0000000000000000 PMD=0000000000000000
	CPU 0: Put process  4 to run queue
	CPU 0: Dispatched process  4
liballoc:193
print_pgtbl:
 PDG=0000000000000000 P4g=0000000000000000 PUD=0000000000000000 PMD=0000000000000000
	CPU 1: Put process  6 to run queue
Time slot  13
	CPU 2: Put process  3 to run queue
	CPU 1: Dispatched process  6
	CPU 2: Dispatched process  3
	Loaded a process at input/proc/s2, PID: 7 PRIO: 120
	CPU 3: Put process  5 to run queue
	CPU 3: Dispatched process  5
Time slot  14
libfree:217
print_pgtbl:
 PDG=0000000000000000 P4g=0000000000000000 PUD=0000000000000000 PMD=0000000000000000
	CPU 0: Put process  4 to run queue
	CPU 0: Dispatched process  4
Time slot  15
libfree:217
print_pgtbl:
 PDG=0000000000000000 P4g=0000000000000000 PUD=0000000000000000 PMD=0000000000000000
	CPU 1: Put process  6 to run queue
	CPU 1: Dispatched process  6
	CPU 2: Put process  3 to run queue
	CPU 2: Dispatched process  3
Time slot  16
	CPU 2: Processed  3 has finished
	CPU 2: Dispatched process  7
	CPU 3: Processed  5 has finished
	CPU 3: Dispatched process  1
print_pgtbl:
 PDG=00000266c02cc850 P4g=00000266c02cd860 PUD=00000266c02ce870 PMD=00000266c02cf880
	Loaded a process at input/proc/s1, PID: 8 PRIO: 0
	CPU 0: Put process  4 to run queue
	CPU 0: Dispatched process  8
Time slot  17
	CPU 1: Put process  6 to run queue
	CPU 1: Dispatched process  6
	CPU 2: Put process  7 to run queue
Time slot  18
	CPU 2: Dispatched process  4
	CPU 3: Put process  1 to run queue
	CPU 0: Put process  8 to run queue
	CPU 3: Dispatched process  7
	CPU 0: Dispatched process  8
Time slot  19
	CPU 1: Put process  6 to run queue
	CPU 1: Dispatched process  6
	CPU 3: Put process  7 to run queue
	CPU 3: Dispatched process  7
Time slot  20
	CPU 0: Put process  8 to run queue
	CPU 2: Put process  4 to run queue
	CPU 0: Dispatched process  8
	CPU 2: Dispatched process  4
	CPU 1: Processed  6 has finished
Time slot  21
	CPU 1: Dispatched process  1
libfree:217
print_pgtbl:
 PDG=00000266c02cc850 P4g=00000266c02cd860 PUD=00000266c02ce870 PMD=00000266c02cf880
	CPU 3: Put process  7 to run queue
	CPU 3: Dispatched process  7
	CPU 2: Put process  4 to run queue
Time slot  22
	CPU 2: Dispatched process  4
	CPU 0: Put process  8 to run queue
	CPU 0: Dispatched process  8
Time slot  23
	CPU 2: Processed  4 has finished
	CPU 1: Processed  1 has finished
	CPU 2 stopped
	CPU 0: Processed  8 has finished
	CPU 1 stopped
	CPU 0 stopped
Time slot  24
	CPU 3: Put process  7 to run queue
	CPU 3: Dispatched process  7
Time slot  25
Time slot  26
	CPU 3: Put process  7 to run queue
	CPU 3: Dispatched process  7
Time slot  27
Time slot  28
	CPU 3: Processed  7 has finished
	CPU 3 stopped
