Time slot   0
ld_routine
Time slot   1
	Loaded a process at input/proc/p0s, PID: 1 PRIO: 130
	CPU 1: Dispatched process  1
Time slot   2
liballoc:193
print_pgtbl:
 PDG=0000017ADCD7F280 P4g=0000017ADCD80290 PUD=0000017ADCD812A0 PMD=0000017ADCD822B0
	Loaded a process at input/proc/m0s, PID: 2 PRIO: 120
Time slot   3
	CPU 1: Put process  1 to run queue
	CPU 1: Dispatched process  2
liballoc:193
print_pgtbl:
 PDG=0000000000000000 P4g=0000000000000000 PUD=0000000000000000 PMD=0000000000000000
	CPU 2: Dispatched process  1
liballoc:193
print_pgtbl:
 PDG=0000017ADCD7F280 P4g=0000017ADCD80290 PUD=0000017ADCD812A0 PMD=0000017ADCD822B0
Time slot   4
	Loaded a process at input/proc/s3, PID: 3 PRIO: 39
liballoc:193
print_pgtbl:
 PDG=0000000000000000 P4g=0000000000000000 PUD=0000000000000000 PMD=0000000000000000
	CPU 0: Dispatched process  3
libfree:217
print_pgtbl:
 PDG=0000017ADCD7F280 P4g=0000017ADCD80290 PUD=0000017ADCD812A0 PMD=0000017ADCD822B0
Time slot   5
	CPU 1: Put process  2 to run queue
	CPU 2: Put process  1 to run queue
	CPU 1: Dispatched process  2
libfree:217
print_pgtbl:
 PDG=0000000000000000 P4g=0000000000000000 PUD=0000000000000000 PMD=0000000000000000
	CPU 2: Dispatched process  1
liballoc:193
print_pgtbl:
 PDG=0000017ADCD7F280 P4g=0000017ADCD80290 PUD=0000017ADCD812A0 PMD=0000017ADCD822B0
	Loaded a process at input/proc/s0, PID: 4 PRIO: 38
	CPU 3: Dispatched process  4
Time slot   6
liballoc:193
print_pgtbl:
 PDG=0000000000000000 P4g=0000000000000000 PUD=0000000000000000 PMD=0000000000000000
	CPU 0: Put process  3 to run queue
libwrite:471
print_pgtbl:
 PDG=0000017ADCD7F280 P4g=0000017ADCD80290 PUD=0000017ADCD812A0 PMD=0000017ADCD822B0
	CPU 0: Dispatched process  3
	CPU 2: Put process  1 to run queue
	CPU 1: Put process  2 to run queue
Time slot   7
	CPU 2: Dispatched process  1
libread:416
print_pgtbl:
 PDG=0000017ADCD7F280 P4g=0000017ADCD80290 PUD=0000017ADCD812A0 PMD=0000017ADCD822B0
	CPU 1: Dispatched process  2
Time slot   8
	CPU 0: Put process  3 to run queue
libwrite:471
print_pgtbl:
	CPU 0: Dispatched process  3
 PDG=0000017ADCD7F280 P4g=0000017ADCD80290 PUD=0000017ADCD812A0 PMD=0000017ADCD822B0
	CPU 3: Put process  4 to run queue
	CPU 3: Dispatched process  4
	Loaded a process at input/proc/m1s, PID: 5 PRIO: 15
Time slot   9
	CPU 2: Put process  1 to run queue
	CPU 2: Dispatched process  5
liballoc:193
print_pgtbl:
 PDG=0000000000000000 P4g=0000000000000000 PUD=0000000000000000 PMD=0000000000000000
	CPU 1: Processed  2 has finished
	CPU 1: Dispatched process  1
print_pgtbl:
 PDG=0000017ADCD7F280 P4g=0000017ADCD80290 PUD=0000017ADCD812A0 PMD=0000017ADCD822B0
Time slot  10
	CPU 3: Put process  4 to run queue
libwrite:471
	CPU 3: Dispatched process  4
print_pgtbl:
 PDG=0000017ADCD7F280 P4g=0000017ADCD80290 PUD=0000017ADCD812A0 PMD=0000017ADCD822B0
	CPU 0: Put process  3 to run queue
	CPU 0: Dispatched process  3
liballoc:193
print_pgtbl:
 PDG=0000000000000000 P4g=0000000000000000 PUD=0000000000000000 PMD=0000000000000000
Time slot  11
	CPU 2: Put process  5 to run queue
	CPU 2: Dispatched process  5
	CPU 1: Put process  1 to run queue
libfree:217
print_pgtbl:
 PDG=0000000000000000 P4g=0000000000000000 PUD=0000000000000000 PMD=0000000000000000
	CPU 1: Dispatched process  1
print_pgtbl:
 PDG=0000017ADCD7F280 P4g=0000017ADCD80290 PUD=0000017ADCD812A0 PMD=0000017ADCD822B0
	Loaded a process at input/proc/p1s, PID: 6 PRIO: 15
Time slot  12
liballoc:193
print_pgtbl:
 PDG=0000000000000000 P4g=0000000000000000 PUD=0000000000000000 PMD=0000000000000000
	CPU 0: Put process  3 to run queue
	CPU 3: Put process  4 to run queue
	CPU 0: Dispatched process  6
	CPU 3: Dispatched process  4
Time slot  13
	CPU 2: Put process  5 to run queue
	CPU 2: Dispatched process  5
libfree:217
	CPU 1: Put process  1 to run queue
print_pgtbl:
 PDG=0000000000000000 P4g=0000000000000000 PUD=0000000000000000 PMD=0000000000000000
	CPU 1: Dispatched process  3
	Loaded a process at input/proc/s2, PID: 7 PRIO: 120
	CPU 3: Put process  4 to run queue
Time slot  14
	CPU 3: Dispatched process  4
	CPU 0: Put process  6 to run queue
	CPU 0: Dispatched process  6
libfree:217
print_pgtbl:
 PDG=0000000000000000 P4g=0000000000000000 PUD=0000000000000000 PMD=0000000000000000
Time slot  15
	CPU 2: Processed  5 has finished
	CPU 2: Dispatched process  7
	CPU 1: Put process  3 to run queue
	CPU 1: Dispatched process  3
Time slot  16
	CPU 3: Put process  4 to run queue
	Loaded a process at input/proc/s1, PID: 8 PRIO: 0
	CPU 1: Processed  3 has finished
	CPU 3: Dispatched process  4
	CPU 1: Dispatched process  8
	CPU 0: Put process  6 to run queue
	CPU 0: Dispatched process  6
	CPU 2: Put process  7 to run queue
Time slot  17
	CPU 2: Dispatched process  7
	CPU 3: Put process  4 to run queue
	CPU 3: Dispatched process  4
Time slot  18
	CPU 1: Put process  8 to run queue
	CPU 0: Put process  6 to run queue
	CPU 1: Dispatched process  8
	CPU 0: Dispatched process  6
Time slot  19
	CPU 2: Put process  7 to run queue
	CPU 2: Dispatched process  7
	CPU 3: Put process  4 to run queue
	CPU 3: Dispatched process  4
Time slot  20
	CPU 0: Put process  6 to run queue
	CPU 1: Put process  8 to run queue
	CPU 0: Dispatched process  6
	CPU 1: Dispatched process  8
	CPU 3: Processed  4 has finished
Time slot  21
	CPU 3: Dispatched process  1
libfree:217
print_pgtbl:
 PDG=0000017ADCD7F280 P4g=0000017ADCD80290 PUD=0000017ADCD812A0 PMD=0000017ADCD822B0
	CPU 2: Put process  7 to run queue
	CPU 2: Dispatched process  7
Time slot  22
	CPU 1: Put process  8 to run queue
	CPU 1: Dispatched process  8
	CPU 0: Processed  6 has finished
	CPU 0 stopped
Time slot  23
	CPU 3: Processed  1 has finished
	CPU 1: Processed  8 has finished
	CPU 3 stopped
	CPU 1 stopped
	CPU 2: Put process  7 to run queue
	CPU 2: Dispatched process  7
Time slot  24
Time slot  25
	CPU 2: Put process  7 to run queue
	CPU 2: Dispatched process  7
Time slot  26
Time slot  27
	CPU 2: Processed  7 has finished
	CPU 2 stopped
