Time slot   0
ld_routine
Time slot   1
	Loaded a process at input/proc/p1s, PID: 1 PRIO: 15
	CPU 0: Dispatched process  1
Time slot   2
Time slot   3
	CPU 0: Put process  1 to run queue
	CPU 0: Dispatched process  1
Time slot   4
Time slot   5
	CPU 0: Put process  1 to run queue
	CPU 0: Dispatched process  1
	Loaded a process at input/proc/m0s, PID: 2 PRIO: 120
	CPU 3: Dispatched process  2
Time slot   6
liballoc:193
print_pgtbl:
 PDG=00000183806153c0 P4g=00000183ff46e010 PUD=00000183ff46f020 PMD=00000183ff470030
Time slot   7
	CPU 0: Put process  1 to run queue
liballoc:193
	CPU 0: Dispatched process  1
print_pgtbl:
 PDG=00000183806153c0 P4g=00000183ff46e010 PUD=00000183ff46f020 PMD=00000183ff470030
	Loaded a process at input/proc/p0s, PID: 3 PRIO: 130
Time slot   8
	CPU 1: Dispatched process  3
	CPU 3: Put process  2 to run queue
	CPU 3: Dispatched process  2
libfree:217
print_pgtbl:
 PDG=00000183806153c0 P4g=00000183ff46e010 PUD=00000183ff46f020 PMD=00000183ff470030
Time slot   9
	Loaded a process at input/proc/s0, PID: 4 PRIO: 38
	CPU 2: Dispatched process  4
	CPU 0: Put process  1 to run queue
	CPU 0: Dispatched process  1
liballoc:193
print_pgtbl:
 PDG=00000183806153c0 P4g=00000183ff46e010 PUD=00000183ff46f020 PMD=00000183ff470030
liballoc:193
print_pgtbl:
 PDG=00000183fe4a0060 P4g=00000183fe4a50b0 PUD=00000183fe4a60c0 PMD=00000183fe4a40a0
Time slot  10
	CPU 3: Put process  2 to run queue
	CPU 3: Dispatched process  2
	CPU 1: Put process  3 to run queue
	CPU 1: Dispatched process  3
libwrite:471
liballoc:193
print_pgtbl:
 PDG=00000183806153c0 P4g=00000183ff46e010 PUD=00000183ff46f020 PMD=00000183ff470030
print_pgtbl:
 PDG=00000183fe4a0060 P4g=00000183fe4a50b0 PUD=00000183fe4a60c0 PMD=00000183fe4a40a0
Time slot  11
	CPU 0: Processed  1 has finished
	CPU 2: Put process  4 to run queue
	CPU 2: Dispatched process  4
libwrite:471
print_pgtbl:
 PDG=00000183806153c0 P4g=00000183ff46e010 PUD=00000183ff46f020 PMD=00000183ff470030
libfree:217
print_pgtbl:
 PDG=00000183fe4a0060 P4g=00000183fe4a50b0 PUD=00000183fe4a60c0 PMD=00000183fe4a40a0
	Loaded a process at input/proc/s3, PID: 5 PRIO: 39
	CPU 3: Processed  2 has finished
Time slot  12
	CPU 3: Dispatched process  5
	CPU 1: Put process  3 to run queue
	CPU 1: Dispatched process  3
liballoc:193
print_pgtbl:
 PDG=00000183fe4a0060 P4g=00000183fe4a50b0 PUD=00000183fe4a60c0 PMD=00000183fe4a40a0
Time slot  13
	CPU 2: Put process  4 to run queue
	CPU 2: Dispatched process  4
libwrite:471
print_pgtbl:
 PDG=00000183fe4a0060 P4g=00000183fe4a50b0 PUD=00000183fe4a60c0 PMD=00000183fe4a40a0
Time slot  14
	Loaded a process at input/proc/m1s, PID: 6 PRIO: 15
	CPU 3: Put process  5 to run queue
	CPU 1: Put process  3 to run queue
	CPU 3: Dispatched process  5
	CPU 0: Dispatched process  6
	CPU 1: Dispatched process  3
libread:416
print_pgtbl:
 PDG=00000183fe4a0060 P4g=00000183fe4a50b0 PUD=00000183fe4a60c0 PMD=00000183fe4a40a0
liballoc:193
print_pgtbl:
 PDG=00000183fe4a80e0 P4g=00000183fe4ac120 PUD=00000183fe4ad130 PMD=00000183fe4ae140
Time slot  15
liballoc:193
print_pgtbl:
 PDG=00000183fe4a80e0 P4g=00000183fe4ac120 PUD=00000183fe4ad130 PMD=00000183fe4ae140
libwrite:471
	CPU 2: Put process  4 to run queue
print_pgtbl:
	CPU 2: Dispatched process  4
 PDG=00000183fe4a0060 P4g=00000183fe4a50b0 PUD=00000183fe4a60c0 PMD=00000183fe4a40a0
Time slot  16
	CPU 0: Put process  6 to run queue
	CPU 0: Dispatched process  6
	CPU 1: Put process  3 to run queue
libfree:217
print_pgtbl:
	CPU 1: Dispatched process  3
 PDG=00000183fe4a80e0 P4g=00000183fe4ac120 PUD=00000183fe4ad130 PMD=00000183fe4ae140
print_pgtbl:
 PDG=00000183fe4a0060 P4g=00000183fe4a50b0 PUD=00000183fe4a60c0 PMD=00000183fe4a40a0
	CPU 3: Put process  5 to run queue
	CPU 3: Dispatched process  5
	Loaded a process at input/proc/s2, PID: 7 PRIO: 120
Time slot  17
	CPU 2: Put process  4 to run queue
	CPU 2: Dispatched process  4
libwrite:471
print_pgtbl:
 PDG=00000183fe4a0060 P4g=00000183fe4a50b0 PUD=00000183fe4a60c0 PMD=00000183fe4a40a0
liballoc:193
print_pgtbl:
 PDG=00000183fe4a80e0 P4g=00000183fe4ac120 PUD=00000183fe4ad130 PMD=00000183fe4ae140
	Loaded a process at input/proc/s1, PID: 8 PRIO: 0
Time slot  18
	CPU 3: Put process  5 to run queue
	CPU 0: Put process  6 to run queue
	CPU 3: Dispatched process  8
	CPU 1: Put process  3 to run queue
	CPU 0: Dispatched process  6
	CPU 1: Dispatched process  5
libfree:217
print_pgtbl:
 PDG=00000183fe4a80e0 P4g=00000183fe4ac120 PUD=00000183fe4ad130 PMD=00000183fe4ae140
Time slot  19
libfree:217
print_pgtbl:
 PDG=00000183fe4a80e0 P4g=00000183fe4ac120 PUD=00000183fe4ad130 PMD=00000183fe4ae140
	CPU 2: Put process  4 to run queue
	CPU 2: Dispatched process  4
	CPU 3: Put process  8 to run queue
	CPU 3: Dispatched process  8
Time slot  20
	CPU 1: Put process  5 to run queue
	CPU 1: Dispatched process  5
	CPU 0: Processed  6 has finished
	CPU 0: Dispatched process  7
Time slot  21
	CPU 2: Put process  4 to run queue
	CPU 2: Dispatched process  4
	CPU 3: Put process  8 to run queue
	CPU 3: Dispatched process  8
Time slot  22
	CPU 1: Put process  5 to run queue
	CPU 1: Dispatched process  5
	CPU 0: Put process  7 to run queue
	CPU 0: Dispatched process  7
Time slot  23
	CPU 2: Put process  4 to run queue
	CPU 2: Dispatched process  4
	CPU 1: Processed  5 has finished
	CPU 1: Dispatched process  3
print_pgtbl:
 PDG=00000183fe4a0060 P4g=00000183fe4a50b0 PUD=00000183fe4a60c0 PMD=00000183fe4a40a0
	CPU 3: Put process  8 to run queue
Time slot  24
	CPU 3: Dispatched process  8
	CPU 2: Processed  4 has finished
	CPU 2 stopped
	CPU 0: Put process  7 to run queue
	CPU 0: Dispatched process  7
Time slot  25
	CPU 3: Processed  8 has finished
	CPU 3 stopped
	CPU 1: Put process  3 to run queue
	CPU 1: Dispatched process  3
libfree:217
print_pgtbl:
 PDG=00000183fe4a0060 P4g=00000183fe4a50b0 PUD=00000183fe4a60c0 PMD=00000183fe4a40a0
Time slot  26
	CPU 0: Put process  7 to run queue
	CPU 0: Dispatched process  7
Time slot  27
	CPU 1: Processed  3 has finished
	CPU 1 stopped
Time slot  28
	CPU 0: Put process  7 to run queue
	CPU 0: Dispatched process  7
Time slot  29
Time slot  30
	CPU 0: Put process  7 to run queue
	CPU 0: Dispatched process  7
Time slot  31
Time slot  32
	CPU 0: Processed  7 has finished
	CPU 0 stopped
