Time slot   0
ld_routine
Time slot   1
	Loaded a process at input/proc/p1s, PID: 1 PRIO: 15
	CPU 2: Dispatched process  1
Time slot   2
Time slot   3
	CPU 2: Put process  1 to run queue
Time slot   4
	CPU 2: Dispatched process  1
	Loaded a process at input/proc/m0s, PID: 2 PRIO: 120
Time slot   5
	CPU 3: Dispatched process  2
liballoc:193
print_pgtbl:
 PDG=000001a11a2b55b0 P4g=000001a117eb0020 PUD=000001a117eb1030 PMD=000001a117eb2040
Time slot   6
	CPU 2: Put process  1 to run queue
	CPU 2: Dispatched process  1
liballoc:193
print_pgtbl:
 PDG=000001a11a2b55b0 P4g=000001a117eb0020 PUD=000001a117eb1030 PMD=000001a117eb2040
Time slot   7
	CPU 3: Put process  2 to run queue
	CPU 3: Dispatched process  2
	Loaded a process at input/proc/p0s, PID: 3 PRIO: 130
libfree:217
print_pgtbl:
 PDG=000001a11a2b55b0 P4g=000001a117eb0020 PUD=000001a117eb1030 PMD=000001a117eb2040
Time slot   8
	CPU 1: Dispatched process  3
	CPU 2: Put process  1 to run queue
liballoc:193
	CPU 2: Dispatched process  1
print_pgtbl:
 PDG=000001a11a2b55b0 P4g=000001a117eb0020 PUD=000001a117eb1030 PMD=000001a117eb2040
Time slot   9
	CPU 3: Put process  2 to run queue
	CPU 3: Dispatched process  2
liballoc:193
print_pgtbl:
 PDG=000001a118cb2080 P4g=000001a118cb0060 PUD=000001a118cb60c0 PMD=000001a118cb70d0
libwrite:471
	Loaded a process at input/proc/s0, PID: 4 PRIO: 38
print_pgtbl:
 PDG=000001a11a2b55b0 P4g=000001a117eb0020 PUD=000001a117eb1030 PMD=000001a117eb2040
Time slot  10
	CPU 2: Put process  1 to run queue
	CPU 2: Dispatched process  1
libwrite:471
print_pgtbl:
 PDG=000001a11a2b55b0 P4g=000001a117eb0020 PUD=000001a117eb1030 PMD=000001a117eb2040
	CPU 1: Put process  3 to run queue
	CPU 1: Dispatched process  4
	CPU 0: Dispatched process  3
liballoc:193
print_pgtbl:
 PDG=000001a118cb2080 P4g=000001a118cb0060 PUD=000001a118cb60c0 PMD=000001a118cb70d0
Time slot  11
	Loaded a process at input/proc/s3, PID: 5 PRIO: 39
	CPU 3: Processed  2 has finished
libfree:217
	CPU 3: Dispatched process  5
print_pgtbl:
 PDG=000001a118cb2080 P4g=000001a118cb0060 PUD=000001a118cb60c0 PMD=000001a118cb70d0
Time slot  12
	CPU 1: Put process  4 to run queue
	CPU 2: Processed  1 has finished
	CPU 1: Dispatched process  4
	CPU 0: Put process  3 to run queue
	CPU 0: Dispatched process  3
liballoc:193
print_pgtbl:
 PDG=000001a118cb2080 P4g=000001a118cb0060 PUD=000001a118cb60c0 PMD=000001a118cb70d0
	CPU 3: Put process  5 to run queue
Time slot  13
	CPU 3: Dispatched process  5
libwrite:471
print_pgtbl:
 PDG=000001a118cb2080 P4g=000001a118cb0060 PUD=000001a118cb60c0 PMD=000001a118cb70d0
	Loaded a process at input/proc/m1s, PID: 6 PRIO: 15
Time slot  14
	CPU 2: Dispatched process  6
	CPU 0: Put process  3 to run queue
	CPU 1: Put process  4 to run queue
	CPU 0: Dispatched process  3
	CPU 1: Dispatched process  4
libread:416
print_pgtbl:
 PDG=000001a118cb2080 P4g=000001a118cb0060 PUD=000001a118cb60c0 PMD=000001a118cb70d0
liballoc:193
print_pgtbl:
 PDG=000001a118cbc120 P4g=000001a118cb90f0 PUD=000001a118cbe140 PMD=000001a118cbd130
Time slot  15
liballoc:193
libwrite:471
print_pgtbl:
 PDG=000001a118cbc120 P4g=000001a118cb90f0 PUD=000001a118cbe140 PMD=000001a118cbd130
	CPU 3: Put process  5 to run queue
print_pgtbl:
 PDG=000001a118cb2080 P4g=000001a118cb0060 PUD=000001a118cb60c0 PMD=000001a118cb70d0
	CPU 3: Dispatched process  5
	Loaded a process at input/proc/s2, PID: 7 PRIO: 120
Time slot  16
	CPU 1: Put process  4 to run queue
	CPU 2: Put process  6 to run queue
	CPU 0: Put process  3 to run queue
	CPU 2: Dispatched process  6
	CPU 0: Dispatched process  7
	CPU 1: Dispatched process  4
libfree:217
print_pgtbl:
 PDG=000001a118cbc120 P4g=000001a118cb90f0 PUD=000001a118cbe140 PMD=000001a118cbd130
Time slot  17
liballoc:193
print_pgtbl:
 PDG=000001a118cbc120 P4g=000001a118cb90f0 PUD=000001a118cbe140 PMD=000001a118cbd130
	CPU 3: Put process  5 to run queue
	CPU 3: Dispatched process  5
	Loaded a process at input/proc/s1, PID: 8 PRIO: 0
Time slot  18
	CPU 1: Put process  4 to run queue
	CPU 0: Put process  7 to run queue
	CPU 1: Dispatched process  8
	CPU 0: Dispatched process  4
	CPU 2: Put process  6 to run queue
	CPU 2: Dispatched process  6
libfree:217
print_pgtbl:
 PDG=000001a118cbc120 P4g=000001a118cb90f0 PUD=000001a118cbe140 PMD=000001a118cbd130
Time slot  19
	CPU 3: Put process  5 to run queue
	CPU 3: Dispatched process  5
libfree:217
print_pgtbl:
 PDG=000001a118cbc120 P4g=000001a118cb90f0 PUD=000001a118cbe140 PMD=000001a118cbd130
	CPU 2: Processed  6 has finished
Time slot  20
	CPU 2: Dispatched process  7
	CPU 0: Put process  4 to run queue
	CPU 0: Dispatched process  4
	CPU 1: Put process  8 to run queue
	CPU 1: Dispatched process  8
	CPU 3: Put process  5 to run queue
	CPU 3: Dispatched process  5
Time slot  21
	CPU 3: Processed  5 has finished
Time slot  22
	CPU 3: Dispatched process  3
	CPU 1: Put process  8 to run queue
print_pgtbl:
	CPU 1: Dispatched process  8
 PDG=000001a118cb2080 P4g=000001a118cb0060 PUD=000001a118cb60c0 PMD=000001a118cb70d0
	CPU 0: Put process  4 to run queue
	CPU 2: Put process  7 to run queue
	CPU 2: Dispatched process  7
	CPU 0: Dispatched process  4
Time slot  23
libwrite:471
print_pgtbl:
 PDG=000001a118cb2080 P4g=000001a118cb0060 PUD=000001a118cb60c0 PMD=000001a118cb70d0
Time slot  24
	CPU 2: Put process  7 to run queue
	CPU 0: Put process  4 to run queue
	CPU 2: Dispatched process  7
	CPU 0: Dispatched process  4
	CPU 1: Put process  8 to run queue
	CPU 1: Dispatched process  8
	CPU 3: Put process  3 to run queue
	CPU 3: Dispatched process  3
print_pgtbl:
 PDG=000001a118cb2080 P4g=000001a118cb0060 PUD=000001a118cb60c0 PMD=000001a118cb70d0
Time slot  25
	CPU 1: Processed  8 has finished
	CPU 0: Processed  4 has finished
	CPU 1 stopped
	CPU 0 stopped
Time slot  26
	CPU 3: Put process  3 to run queue
	CPU 2: Put process  7 to run queue
	CPU 3: Dispatched process  3
	CPU 2: Dispatched process  7
libfree:217
print_pgtbl:
 PDG=000001a118cb2080 P4g=000001a118cb0060 PUD=000001a118cb60c0 PMD=000001a118cb70d0
Time slot  27
	CPU 3: Processed  3 has finished
Time slot  28
	CPU 3 stopped
	CPU 2: Put process  7 to run queue
	CPU 2: Dispatched process  7
Time slot  29
Time slot  30
	CPU 2: Processed  7 has finished
	CPU 2 stopped
