Time slot   0
ld_routine
Time slot   1
	Loaded a process at input/proc/p1s, PID: 1 PRIO: 15
	CPU 1: Dispatched process  1
Time slot   2
Time slot   3
	CPU 1: Put process  1 to run queue
	CPU 1: Dispatched process  1
Time slot   4
Time slot   5
	CPU 1: Put process  1 to run queue
	CPU 1: Dispatched process  1
	Loaded a process at input/proc/m0s, PID: 2 PRIO: 120
Time slot   6
	CPU 2: Dispatched process  2
liballoc:193
print_pgtbl:
 PDG=000001E8CC405D70 P4g=000001E8CC406D80 PUD=000001E8CE1BE010 PMD=000001E8CE1BF020
Time slot   7
	CPU 1: Put process  1 to run queue
	CPU 1: Dispatched process  1
liballoc:193
print_pgtbl:
 PDG=000001E8CC405D70 P4g=000001E8CC406D80 PUD=000001E8CE1BE010 PMD=000001E8CE1BF020
	Loaded a process at input/proc/p0s, PID: 3 PRIO: 130
Time slot   8
	CPU 3: Dispatched process  3
	CPU 2: Put process  2 to run queue
	CPU 2: Dispatched process  2
libfree:217
print_pgtbl:
 PDG=000001E8CC405D70 P4g=000001E8CC406D80 PUD=000001E8CE1BE010 PMD=000001E8CE1BF020
	Loaded a process at input/proc/s0, PID: 4 PRIO: 38
Time slot   9
liballoc:193
print_pgtbl:
 PDG=000001E8CC405D70 P4g=000001E8CC406D80 PUD=000001E8CE1BE010 PMD=000001E8CE1BF020
	CPU 0: Dispatched process  4
liballoc:193
print_pgtbl:
 PDG=000001E8CC9EF080 P4g=000001E8CC9F20B0 PUD=000001E8CC9F60F0 PMD=000001E8CC9F40D0
	CPU 1: Put process  1 to run queue
	CPU 1: Dispatched process  1
Time slot  10
	CPU 3: Put process  3 to run queue
	CPU 3: Dispatched process  3
liballoc:193
print_pgtbl:
 PDG=000001E8CC9EF080 P4g=000001E8CC9F20B0 PUD=000001E8CC9F60F0 PMD=000001E8CC9F40D0
	CPU 2: Put process  2 to run queue
	CPU 2: Dispatched process  2
libwrite:471
print_pgtbl:
 PDG=000001E8CC405D70 P4g=000001E8CC406D80 PUD=000001E8CE1BE010 PMD=000001E8CE1BF020
Time slot  11
	CPU 1: Processed  1 has finished
libwrite:471
print_pgtbl:
	Loaded a process at input/proc/s3, PID: 5 PRIO: 39
 PDG=000001E8CC405D70 P4g=000001E8CC406D80 PUD=000001E8CE1BE010 PMD=000001E8CE1BF020
	CPU 0: Put process  4 to run queue
	CPU 0: Dispatched process  4
libfree:217
print_pgtbl:
 PDG=000001E8CC9EF080 P4g=000001E8CC9F20B0 PUD=000001E8CC9F60F0 PMD=000001E8CC9F40D0
Time slot  12
	CPU 1: Dispatched process  5
	CPU 3: Put process  3 to run queue
	CPU 3: Dispatched process  3
liballoc:193
print_pgtbl:
 PDG=000001E8CC9EF080 P4g=000001E8CC9F20B0 PUD=000001E8CC9F60F0 PMD=000001E8CC9F40D0
	CPU 2: Processed  2 has finished
Time slot  13
libwrite:471
print_pgtbl:
 PDG=000001E8CC9EF080 P4g=000001E8CC9F20B0 PUD=000001E8CC9F60F0 PMD=000001E8CC9F40D0
	CPU 0: Put process  4 to run queue
	CPU 0: Dispatched process  4
Time slot  14
	CPU 3: Put process  3 to run queue
	CPU 3: Dispatched process  3
	CPU 1: Put process  5 to run queue
libread:416
	Loaded a process at input/proc/m1s, PID: 6 PRIO: 15
	CPU 1: Dispatched process  5
print_pgtbl:
 PDG=000001E8CC9EF080 P4g=000001E8CC9F20B0 PUD=000001E8CC9F60F0 PMD=000001E8CC9F40D0
libwrite:471
print_pgtbl:
 PDG=000001E8CC9EF080 P4g=000001E8CC9F20B0 PUD=000001E8CC9F60F0 PMD=000001E8CC9F40D0
Time slot  15
	CPU 0: Put process  4 to run queue
	CPU 0: Dispatched process  6
	CPU 2: Dispatched process  4
liballoc:193
print_pgtbl:
 PDG=000001E8CC9F8110 P4g=000001E8CC9FB140 PUD=000001E8CC9FC150 PMD=000001E8CC9F9120
Time slot  16
	CPU 3: Put process  3 to run queue
	CPU 3: Dispatched process  3
print_pgtbl:
 PDG=000001E8CC9EF080 P4g=000001E8CC9F20B0 PUD=000001E8CC9F60F0 PMD=000001E8CC9F40D0
	CPU 1: Put process  5 to run queue
	CPU 1: Dispatched process  5
	Loaded a process at input/proc/s2, PID: 7 PRIO: 120
liballoc:193
print_pgtbl:
 PDG=000001E8CC9F8110 P4g=000001E8CC9FB140 PUD=000001E8CC9FC150 PMD=000001E8CC9F9120
Time slot  17
libwrite:471
	CPU 2: Put process  4 to run queue
print_pgtbl:
 PDG=000001E8CC9EF080 P4g=000001E8CC9F20B0 PUD=000001E8CC9F60F0 PMD=000001E8CC9F40D0
	CPU 2: Dispatched process  4
	CPU 0: Put process  6 to run queue
	CPU 0: Dispatched process  6
libfree:217
print_pgtbl:
 PDG=000001E8CC9F8110 P4g=000001E8CC9FB140 PUD=000001E8CC9FC150 PMD=000001E8CC9F9120
	Loaded a process at input/proc/s1, PID: 8 PRIO: 0
Time slot  18
liballoc:193
print_pgtbl:
 PDG=000001E8CC9F8110 P4g=000001E8CC9FB140 PUD=000001E8CC9FC150 PMD=000001E8CC9F9120
	CPU 1: Put process  5 to run queue
	CPU 1: Dispatched process  8
	CPU 3: Put process  3 to run queue
	CPU 3: Dispatched process  5
Time slot  19
	CPU 2: Put process  4 to run queue
	CPU 2: Dispatched process  4
	CPU 0: Put process  6 to run queue
	CPU 0: Dispatched process  6
libfree:217
print_pgtbl:
 PDG=000001E8CC9F8110 P4g=000001E8CC9FB140 PUD=000001E8CC9FC150 PMD=000001E8CC9F9120
Time slot  20
libfree:217
print_pgtbl:
 PDG=000001E8CC9F8110 P4g=000001E8CC9FB140 PUD=000001E8CC9FC150 PMD=000001E8CC9F9120
	CPU 1: Put process  8 to run queue
	CPU 1: Dispatched process  8
	CPU 3: Put process  5 to run queue
	CPU 3: Dispatched process  5
Time slot  21
	CPU 2: Put process  4 to run queue
	CPU 2: Dispatched process  4
	CPU 0: Processed  6 has finished
	CPU 0: Dispatched process  7
Time slot  22
	CPU 3: Put process  5 to run queue
	CPU 3: Dispatched process  5
	CPU 1: Put process  8 to run queue
	CPU 1: Dispatched process  8
Time slot  23
	CPU 3: Processed  5 has finished
	CPU 3: Dispatched process  3
print_pgtbl:
 PDG=000001E8CC9EF080 P4g=000001E8CC9F20B0 PUD=000001E8CC9F60F0 PMD=000001E8CC9F40D0
	CPU 2: Put process  4 to run queue
	CPU 2: Dispatched process  4
	CPU 0: Put process  7 to run queue
	CPU 0: Dispatched process  7
Time slot  24
	CPU 1: Put process  8 to run queue
	CPU 1: Dispatched process  8
	CPU 2: Processed  4 has finished
	CPU 2 stopped
Time slot  25
	CPU 3: Put process  3 to run queue
	CPU 3: Dispatched process  3
libfree:217
print_pgtbl:
 PDG=000001E8CC9EF080 P4g=000001E8CC9F20B0 PUD=000001E8CC9F60F0 PMD=000001E8CC9F40D0
	CPU 1: Processed  8 has finished
	CPU 1 stopped
	CPU 0: Put process  7 to run queue
	CPU 0: Dispatched process  7
Time slot  26
Time slot  27
	CPU 3: Processed  3 has finished
	CPU 3 stopped
	CPU 0: Put process  7 to run queue
	CPU 0: Dispatched process  7
Time slot  28
Time slot  29
	CPU 0: Put process  7 to run queue
	CPU 0: Dispatched process  7
Time slot  30
Time slot  31
	CPU 0: Put process  7 to run queue
	CPU 0: Dispatched process  7
Time slot  32
Time slot  33
	CPU 0: Processed  7 has finished
	CPU 0 stopped
