Time slot   0
ld_routine
Time slot   1
Time slot   2
Time slot   3
Time slot   4
Time slot   5
	Loaded a process at input/proc/m2s, PID: 1 PRIO: 120
Time slot   6
	CPU 3: Dispatched process  1
liballoc:193
print_pgtbl:
 PDG=000001E08C4CCD20 P4g=000001E08C4CDD30 PUD=000001E08C4CED40 PMD=000001E08C4CFD50
Time slot   7
liballoc:193
print_pgtbl:
 PDG=000001E08C4CCD20 P4g=000001E08C4CDD30 PUD=000001E08C4CED40 PMD=000001E08C4CFD50
Time slot   8
	CPU 3: Put process  1 to run queue
	CPU 3: Dispatched process  1
libfree:217
print_pgtbl:
 PDG=000001E08C4CCD20 P4g=000001E08C4CDD30 PUD=000001E08C4CED40 PMD=000001E08C4CFD50
Time slot   9
	Loaded a process at input/proc/s0, PID: 2 PRIO: 38
	CPU 1: Dispatched process  2
Time slot  10
	CPU 3: Put process  1 to run queue
	CPU 3: Dispatched process  1
	Loaded a process at input/proc/s3, PID: 3 PRIO: 39
Time slot  11
	CPU 0: Dispatched process  3
	CPU 1: Put process  2 to run queue
	CPU 1: Dispatched process  2
Time slot  12
	CPU 3: Put process  1 to run queue
	CPU 3: Dispatched process  1
Time slot  13
	CPU 1: Put process  2 to run queue
	CPU 1: Dispatched process  2
	CPU 0: Put process  3 to run queue
	CPU 0: Dispatched process  3
	Loaded a process at input/proc/m2s, PID: 4 PRIO: 15
Time slot  14
	CPU 3: Put process  1 to run queue
	CPU 3: Dispatched process  4
liballoc:193
print_pgtbl:
 PDG=000001E08B0950F0 P4g=000001E08B0930D0 PUD=000001E08B0920C0 PMD=000001E08B099130
	CPU 2: Dispatched process  1
Time slot  15
	CPU 1: Put process  2 to run queue
	CPU 1: Dispatched process  2
liballoc:193
	CPU 0: Put process  3 to run queue
print_pgtbl:
 PDG=000001E08B0950F0 P4g=000001E08B0930D0 PUD=000001E08B0920C0 PMD=000001E08B099130
	CPU 0: Dispatched process  3
	Loaded a process at input/proc/s2, PID: 5 PRIO: 120
Time slot  16
	CPU 3: Put process  4 to run queue
	CPU 3: Dispatched process  4
libfree:217
print_pgtbl:
 PDG=000001E08B0950F0 P4g=000001E08B0930D0 PUD=000001E08B0920C0 PMD=000001E08B099130
	CPU 2: Put process  1 to run queue
	CPU 2: Dispatched process  5
Time slot  17
	CPU 1: Put process  2 to run queue
	CPU 1: Dispatched process  2
	CPU 0: Put process  3 to run queue
	CPU 0: Dispatched process  3
	Loaded a process at input/proc/s1, PID: 6 PRIO: 0
Time slot  18
	CPU 3: Put process  4 to run queue
	CPU 3: Dispatched process  6
	CPU 2: Put process  5 to run queue
	CPU 2: Dispatched process  4
Time slot  19
	CPU 1: Put process  2 to run queue
	CPU 0: Put process  3 to run queue
	CPU 1: Dispatched process  2
	CPU 0: Dispatched process  3
Time slot  20
	CPU 3: Put process  6 to run queue
	CPU 3: Dispatched process  6
	CPU 2: Put process  4 to run queue
	CPU 2: Dispatched process  4
Time slot  21
	CPU 0: Put process  3 to run queue
	CPU 0: Dispatched process  3
	CPU 1: Put process  2 to run queue
	CPU 1: Dispatched process  2
	CPU 3: Put process  6 to run queue
Time slot  22
	CPU 3: Dispatched process  6
	CPU 0: Processed  3 has finished
	CPU 0: Dispatched process  1
libfree:217
print_pgtbl:
 PDG=000001E08C4CCD20 P4g=000001E08C4CDD30 PUD=000001E08C4CED40 PMD=000001E08C4CFD50
	CPU 2: Put process  4 to run queue
	CPU 2: Dispatched process  4
Time slot  23
	CPU 1: Put process  2 to run queue
	CPU 1: Dispatched process  2
	CPU 2: Put process  4 to run queue
	CPU 2: Dispatched process  4
	CPU 3: Put process  6 to run queue
Time slot  24
libfree:217
	CPU 3: Dispatched process  6
print_pgtbl:
 PDG=000001E08B0950F0 P4g=000001E08B0930D0 PUD=000001E08B0920C0 PMD=000001E08B099130
	CPU 1: Processed  2 has finished
	CPU 1: Dispatched process  5
	CPU 0: Processed  1 has finished
	CPU 0 stopped
Time slot  25
	CPU 3: Processed  6 has finished
	CPU 3 stopped
Time slot  26
	CPU 1: Put process  5 to run queue
	CPU 2: Processed  4 has finished
	CPU 1: Dispatched process  5
	CPU 2 stopped
Time slot  27
Time slot  28
	CPU 1: Put process  5 to run queue
	CPU 1: Dispatched process  5
Time slot  29
Time slot  30
	CPU 1: Put process  5 to run queue
	CPU 1: Dispatched process  5
Time slot  31
Time slot  32
	CPU 1: Put process  5 to run queue
	CPU 1: Dispatched process  5
Time slot  33
Time slot  34
	CPU 1: Processed  5 has finished
	CPU 1 stopped
